<?xml version="1.0" encoding="UTF-8"?>
<!-- Generated by org.testng.reporters.JUnitReportReporter -->
<testsuite skipped="6" hostname="AMX-RL-19-255-W" name="TestNGPkg.TestNGHardAssert" tests="8" failures="2" timestamp="2020-12-05T18:10:26 IST" time="0.033" errors="0">
  <testcase name="hardAssert1" time="0.002" classname="TestNGPkg.TestNGHardAssert">
    <skipped/>
  </testcase> <!-- hardAssert1 -->
  <system-out/>
  <testcase name="hardAssert1" time="0.002" classname="TestNGPkg.TestNGHardAssert">
    <failure type="java.lang.AssertionError" message="expected [sman] but found [man]">
      <![CDATA[java.lang.AssertionError: expected [sman] but found [man]
at org.testng.Assert.fail(Assert.java:97)
at org.testng.Assert.assertEqualsImpl(Assert.java:136)
at org.testng.Assert.assertEquals(Assert.java:118)
at org.testng.Assert.assertEquals(Assert.java:575)
at org.testng.Assert.assertEquals(Assert.java:585)
at TestNGPkg.TestNGHardAssert.hardAssert1(TestNGHardAssert.java:18)
at sun.reflect.NativeMethodAccessorImpl.invoke0(Native Method)
at sun.reflect.NativeMethodAccessorImpl.invoke(Unknown Source)
at sun.reflect.DelegatingMethodAccessorImpl.invoke(Unknown Source)
at java.lang.reflect.Method.invoke(Unknown Source)
at org.testng.internal.MethodInvocationHelper.invokeMethod(MethodInvocationHelper.java:134)
at org.testng.internal.TestInvoker.invokeMethod(TestInvoker.java:597)
at org.testng.internal.TestInvoker.retryFailed(TestInvoker.java:213)
at org.testng.internal.MethodRunner.runInSequence(MethodRunner.java:58)
at org.testng.internal.TestInvoker$MethodInvocationAgent.invoke(TestInvoker.java:816)
at org.testng.internal.TestInvoker.invokeTestMethods(TestInvoker.java:146)
at org.testng.internal.TestMethodWorker.invokeTestMethods(TestMethodWorker.java:146)
at org.testng.internal.TestMethodWorker.run(TestMethodWorker.java:128)
at java.util.ArrayList.forEach(Unknown Source)
at org.testng.TestRunner.privateRun(TestRunner.java:766)
at org.testng.TestRunner.run(TestRunner.java:587)
at org.testng.SuiteRunner.runTest(SuiteRunner.java:384)
at org.testng.SuiteRunner.runSequentially(SuiteRunner.java:378)
at org.testng.SuiteRunner.privateRun(SuiteRunner.java:337)
at org.testng.SuiteRunner.run(SuiteRunner.java:286)
at org.testng.SuiteRunnerWorker.runSuite(SuiteRunnerWorker.java:53)
at org.testng.SuiteRunnerWorker.run(SuiteRunnerWorker.java:96)
at org.testng.TestNG.runSuitesSequentially(TestNG.java:1187)
at org.testng.TestNG.runSuitesLocally(TestNG.java:1109)
at org.testng.TestNG.runSuites(TestNG.java:1039)
at org.testng.TestNG.run(TestNG.java:1007)
at org.testng.remote.AbstractRemoteTestNG.run(AbstractRemoteTestNG.java:115)
at org.testng.remote.RemoteTestNG.initAndRun(RemoteTestNG.java:251)
at org.testng.remote.RemoteTestNG.main(RemoteTestNG.java:77)
]]>
    </failure>
  </testcase> <!-- hardAssert1 -->
  <system-out/>
  <testcase name="hardAssert1" time="0.002" classname="TestNGPkg.TestNGHardAssert">
    <skipped/>
  </testcase> <!-- hardAssert1 -->
  <system-out/>
  <testcase name="softAssert1" time="0.001" classname="TestNGPkg.TestNGHardAssert">
    <skipped/>
  </testcase> <!-- softAssert1 -->
  <system-out/>
  <testcase name="softAssert1" time="0.002" classname="TestNGPkg.TestNGHardAssert">
    <failure type="java.lang.AssertionError" message="The following asserts failed:
	expected [false] but found [true]">
      <![CDATA[java.lang.AssertionError: The following asserts failed:
expected [false] but found [true]
at org.testng.asserts.SoftAssert.assertAll(SoftAssert.java:47)
at org.testng.asserts.SoftAssert.assertAll(SoftAssert.java:31)
at TestNGPkg.TestNGHardAssert.softAssert1(TestNGHardAssert.java:31)
at sun.reflect.NativeMethodAccessorImpl.invoke0(Native Method)
at sun.reflect.NativeMethodAccessorImpl.invoke(Unknown Source)
at sun.reflect.DelegatingMethodAccessorImpl.invoke(Unknown Source)
at java.lang.reflect.Method.invoke(Unknown Source)
at org.testng.internal.MethodInvocationHelper.invokeMethod(MethodInvocationHelper.java:134)
at org.testng.internal.TestInvoker.invokeMethod(TestInvoker.java:597)
at org.testng.internal.TestInvoker.retryFailed(TestInvoker.java:213)
at org.testng.internal.MethodRunner.runInSequence(MethodRunner.java:58)
at org.testng.internal.TestInvoker$MethodInvocationAgent.invoke(TestInvoker.java:816)
at org.testng.internal.TestInvoker.invokeTestMethods(TestInvoker.java:146)
at org.testng.internal.TestMethodWorker.invokeTestMethods(TestMethodWorker.java:146)
at org.testng.internal.TestMethodWorker.run(TestMethodWorker.java:128)
at java.util.ArrayList.forEach(Unknown Source)
at org.testng.TestRunner.privateRun(TestRunner.java:766)
at org.testng.TestRunner.run(TestRunner.java:587)
at org.testng.SuiteRunner.runTest(SuiteRunner.java:384)
at org.testng.SuiteRunner.runSequentially(SuiteRunner.java:378)
at org.testng.SuiteRunner.privateRun(SuiteRunner.java:337)
at org.testng.SuiteRunner.run(SuiteRunner.java:286)
at org.testng.SuiteRunnerWorker.runSuite(SuiteRunnerWorker.java:53)
at org.testng.SuiteRunnerWorker.run(SuiteRunnerWorker.java:96)
at org.testng.TestNG.runSuitesSequentially(TestNG.java:1187)
at org.testng.TestNG.runSuitesLocally(TestNG.java:1109)
at org.testng.TestNG.runSuites(TestNG.java:1039)
at org.testng.TestNG.run(TestNG.java:1007)
at org.testng.remote.AbstractRemoteTestNG.run(AbstractRemoteTestNG.java:115)
at org.testng.remote.RemoteTestNG.initAndRun(RemoteTestNG.java:251)
at org.testng.remote.RemoteTestNG.main(RemoteTestNG.java:77)
]]>
    </failure>
  </testcase> <!-- softAssert1 -->
  <system-out/>
  <testcase name="softAssert1" time="0.006" classname="TestNGPkg.TestNGHardAssert">
    <skipped/>
  </testcase> <!-- softAssert1 -->
  <system-out/>
  <testcase name="hardAssert1" time="0.015" classname="TestNGPkg.TestNGHardAssert">
    <skipped/>
  </testcase> <!-- hardAssert1 -->
  <system-out/>
  <testcase name="softAssert1" time="0.003" classname="TestNGPkg.TestNGHardAssert">
    <skipped/>
  </testcase> <!-- softAssert1 -->
  <system-out/>
</testsuite> <!-- TestNGPkg.TestNGHardAssert -->
